<?xml version="1.0"?>
<robot name="simple_car">

    <!-- ==================== MATERIAL DEFINITIONS ==================== -->
    <material name="car_blue">
        <color rgba="0.1 0.5 0.8 1.0"/>
    </material>
    <material name="dark_blue">
        <color rgba="0.05 0.2 0.4 1.0"/>
    </material>
    <material name="tire_black">
        <color rgba="0.05 0.05 0.05 1.0"/>
    </material>
    <material name="hubcap_silver">
        <color rgba="0.9 0.9 0.9 1.0"/>
    </material>
    <material name="windshield">
        <color rgba="0.7 0.9 1.0 0.5"/>
    </material>
    <material name="headlight">
        <color rgba="1.0 0.98 0.8 1.0"/>
    </material>

    <!-- ==================== MAIN BODY ==================== -->
    <link name="base_link">
        <!-- Main chassis -->
        <visual>
            <geometry>
                <box size="0.3 0.5 0.1"/>
            </geometry>
            <material name="car_blue"/>
        </visual>
        
        <!-- Windshield -->
        <visual>
            <origin xyz="0 0.15 0.05" rpy="0 0 0"/>
            <geometry>
                <box size="0.28 0.18 0.01"/>
            </geometry>
            <material name="windshield"/>
        </visual>
        
        <!-- Rear bumper -->
        <visual>
            <origin xyz="0 -0.22 0.0" rpy="0 0 0"/>
            <geometry>
                <box size="0.3 0.06 0.08"/>
            </geometry>
            <material name="dark_blue"/>
        </visual>
        
        <!-- Roof -->
        <visual>
            <origin xyz="0 0 0.075" rpy="0 0 0"/>
            <geometry>
                <box size="0.28 0.5 0.01"/>
            </geometry>
            <material name="dark_blue"/>
        </visual>
        
        <collision>
            <geometry>
                <box size="0.3 0.5 0.1"/>
            </geometry>
        </collision>
        <inertial>
            <mass value="50.0"/>
            <inertia ixx="1.0" ixy="0.0" ixz="0.0" iyy="1.0" iyz="0.0" izz="1.0"/>
        </inertial>
    </link>

    <!-- ==================== WHEELS ==================== -->
    <link name="front_left_wheel">
        <visual>
            <geometry>
                <cylinder radius="0.05" length="0.03"/>
            </geometry>
            <material name="tire_black"/>
        </visual>
        <visual>
            <origin xyz="0 0 0" rpy="1.5707 0 0"/>
            <geometry>
                <cylinder radius="0.035" length="0.005"/>
            </geometry>
            <material name="hubcap_silver"/>
        </visual>
        <collision>
            <geometry>
                <cylinder radius="0.05" length="0.03"/>
            </geometry>
        </collision>
        <inertial>
            <mass value="2.0"/>
            <inertia ixx="0.1" ixy="0.0" ixz="0.0" iyy="0.1" iyz="0.0" izz="0.1"/>
        </inertial>
    </link>

    <link name="front_right_wheel">  
        <visual>  
            <geometry>  
                <cylinder radius="0.05" length="0.03"/>  
            </geometry>  
            <material name="tire_black"/>  
        </visual>
        <visual>
            <origin xyz="0 0 0" rpy="1.5707 0 0"/>
            <geometry>
                <cylinder radius="0.035" length="0.005"/>
            </geometry>
            <material name="hubcap_silver"/>
        </visual>  
        <collision>  
            <geometry>  
                <cylinder radius="0.05" length="0.03"/>  
            </geometry>  
        </collision>  
        <inertial>  
            <mass value="2.0"/>  
            <inertia ixx="0.1" ixy="0.0" ixz="0.0" iyy="0.1" iyz="0.0" izz="0.1"/>  
        </inertial>  
    </link>

    <link name="rear_left_wheel">
        <visual>
            <geometry>
                <cylinder radius="0.05" length="0.03"/>
            </geometry>
            <material name="tire_black"/>
        </visual>
        <visual>
            <origin xyz="0 0 0" rpy="1.5707 0 0"/>
            <geometry>
                <cylinder radius="0.035" length="0.005"/>
            </geometry>
            <material name="hubcap_silver"/>
        </visual>
        <collision>
            <geometry>
                <cylinder radius="0.05" length="0.03"/>
            </geometry>
        </collision>
        <inertial>
            <mass value="2.0"/>
            <inertia ixx="0.1" ixy="0.0" ixz="0.0" iyy="0.1" iyz="0.0" izz="0.1"/>
        </inertial>
    </link>

    <link name="rear_right_wheel">  
        <visual>  
            <geometry>  
                <cylinder radius="0.05" length="0.03"/>  
            </geometry>  
            <material name="tire_black"/>  
        </visual>
        <visual>
            <origin xyz="0 0 0" rpy="1.5707 0 0"/>
            <geometry>
                <cylinder radius="0.035" length="0.005"/>
            </geometry>
            <material name="hubcap_silver"/>
        </visual>  
        <collision>  
            <geometry>  
                <cylinder radius="0.05" length="0.03"/>  
            </geometry>  
        </collision>  
        <inertial>  
            <mass value="2.0"/>  
            <inertia ixx="0.1" ixy="0.0" ixz="0.0" iyy="0.1" iyz="0.0" izz="0.1"/>  
        </inertial>  
    </link>

    <!-- ==================== HEADLIGHTS ==================== -->
    <link name="front_left_headlight">
        <visual>
            <geometry>
                <sphere radius="0.02"/>
            </geometry>
            <material name="headlight"/>
        </visual>
    </link>
    
    <link name="front_right_headlight">
        <visual>
            <geometry>
                <sphere radius="0.02"/>
            </geometry>
            <material name="headlight"/>
        </visual>
    </link>

    <!-- ==================== JOINTS ==================== -->
    <joint name="front_left_wheel_joint" type="continuous">
        <parent link="base_link"/>  
        <child link="front_left_wheel"/>  
        <origin xyz="0.15 0.2 -0.05" rpy="0 1.5707 0"/>
        <axis xyz="0 0 1"/>  
    </joint>  

    <joint name="front_right_wheel_joint" type="continuous">
        <parent link="base_link"/>  
        <child link="front_right_wheel"/>  
        <origin xyz="-0.15 0.2 -0.05" rpy="0 1.5707 0"/>
        <axis xyz="0 0 1"/>  
    </joint>

    <joint name="rear_left_wheel_joint" type="continuous">
        <parent link="base_link"/>  
        <child link="rear_left_wheel"/>  
        <origin xyz="0.15 -0.2 -0.05" rpy="0 1.5707 0"/>
        <axis xyz="0 0 1"/>  
    </joint>  

    <joint name="rear_right_wheel_joint" type="continuous">
        <parent link="base_link"/>  
        <child link="rear_right_wheel"/>  
        <origin xyz="-0.15 -0.2 -0.05" rpy="0 1.5707 0"/>
        <axis xyz="0 0 1"/>  
    </joint>

    <joint name="front_left_headlight_joint" type="fixed">
        <parent link="base_link"/>
        <child link="front_left_headlight"/>
        <origin xyz="0.1 0.25 0.02" rpy="0 0 0"/>
    </joint>
    
    <joint name="front_right_headlight_joint" type="fixed">
        <parent link="base_link"/>
        <child link="front_right_headlight"/>
        <origin xyz="-0.1 0.25 0.02" rpy="0 0 0"/>
    </joint>
    
    <!-- ==================== GAZEBO CONFIGURATION ==================== -->
    <gazebo reference="base_link">
        <material>Gazebo/Blue</material>
    </gazebo>
    <gazebo reference="front_left_wheel">
        <material>Gazebo/Black</material>
    </gazebo>
    <gazebo reference="front_right_wheel">
        <material>Gazebo/Black</material>
    </gazebo>
    <gazebo reference="rear_left_wheel">
        <material>Gazebo/Black</material>
    </gazebo>
    <gazebo reference="rear_right_wheel">
        <material>Gazebo/Black</material>
    </gazebo>
    <gazebo reference="front_left_headlight">
        <material>Gazebo/Yellow</material>
        <emissive>1 1 0.5 1</emissive>
    </gazebo>
    <gazebo reference="front_right_headlight">
        <material>Gazebo/Yellow</material>
        <emissive>1 1 0.5 1</emissive>
    </gazebo>

    <gazebo>  
        <plugin name="differential_drive" filename="libgazebo_ros_diff_drive.so">  
            <command_topic>/cmd_vel</command_topic>  
            <odometry_topic>/odom</odometry_topic>  
            <odometry_frame>odom</odometry_frame>  
            <robot_base_frame>base_link</robot_base_frame>
            <left_joint>rear_left_wheel_joint</left_joint>
            <right_joint>rear_right_wheel_joint</right_joint>
            <wheel_separation>0.3</wheel_separation>
            <wheel_diameter>0.1</wheel_diameter>
            <max_wheel_torque>20.0</max_wheel_torque>
            <max_wheel_acceleration>1.0</max_wheel_acceleration>
            <publish_odom>true</publish_odom>
            <publish_odom_tf>true</publish_odom_tf>
            <publish_wheel_tf>true</publish_wheel_tf>
        </plugin>
    </gazebo>
</robot>
